Workbook
Name _DList: OFFSET('[1]Thong tin'!$B$1,MATCH('[1]Ky bien ban'!$B1,'[1]Thong tin'!$B:$B,0)-1,3,VLOOKUP('[1]Ky bien ban'!$B1,'[1]Thong tin'!$B$1:$H$527,2,0),1)
Name _DList: OFFSET('[1]Thong tin'!$B$1,MATCH('[1]Ky bien ban'!$B1,'[1]Thong tin'!$B:$B,0)-1,3,VLOOKUP('[1]Ky bien ban'!$B1,'[1]Thong tin'!$B$1:$H$527,2,0),1)
Name _DList: OFFSET('[2]Thong tin'!$B$1,MATCH('[2]Ky bien ban'!$B1,'[2]Thong tin'!$B:$B,0)-1,3,VLOOKUP('[2]Ky bien ban'!$B1,'[2]Thong tin'!$B$1:$H$527,2,0),1)
Name _DList: OFFSET('[3]Thong tin'!$B$1,MATCH('[3]Ky bien ban'!$B1,'[3]Thong tin'!$B:$B,0)-1,3,VLOOKUP('[3]Ky bien ban'!$B1,'[3]Thong tin'!$B$1:$H$527,2,0),1)
Name _DList: OFFSET('[3]Thong tin'!$B$1,MATCH('[3]Ky bien ban'!$B1,'[3]Thong tin'!$B:$B,0)-1,3,VLOOKUP('[3]Ky bien ban'!$B1,'[3]Thong tin'!$B$1:$H$527,2,0),1)
Name _DList: OFFSET('[4]Thong tin'!$B$1,MATCH('[4]Ky bien ban'!$B1,'[4]Thong tin'!$B:$B,0)-1,3,VLOOKUP('[4]Ky bien ban'!$B1,'[4]Thong tin'!$B$1:$H$527,2,0),1)
Name _DSthanhphan: OFFSET('[1]Thong tin'!$B$116,0,0,COUNTA([1]Ts!$B$3:$B$10),1)
Name _DSthanhphan: OFFSET('[1]Thong tin'!$B$116,0,0,COUNTA([1]Ts!$B$3:$B$10),1)
Name _DSthanhphan: OFFSET('[2]Thong tin'!$B$116,0,0,COUNTA([2]Ts!$B$3:$B$10),1)
Name _DSthanhphan: OFFSET('[3]Thong tin'!$B$116,0,0,COUNTA([3]Ts!$B$3:$B$10),1)
Name _DSthanhphan: OFFSET('[3]Thong tin'!$B$116,0,0,COUNTA([3]Ts!$B$3:$B$10),1)
Name _DSthanhphan: OFFSET('[4]Thong tin'!$B$116,0,0,COUNTA([4]Ts!$B$3:$B$10),1)
Name _KyLM: '[1]Ky bien ban'!$C$4:$G$8
Name _KyLM: '[1]Ky bien ban'!$C$4:$G$8
Name _KyLM: '[2]Ky bien ban'!$C$4:$G$8
Name _KyLM: '[3]Ky bien ban'!$C$4:$G$8
Name _KyLM: '[3]Ky bien ban'!$C$4:$G$8
Name _KyLM: '[4]Ky bien ban'!$C$4:$G$8
Name _KyNoibo: '[1]Ky bien ban'!$C$11:$G$17
Name _KyNoibo: '[1]Ky bien ban'!$C$11:$G$17
Name _KyNoibo: '[2]Ky bien ban'!$C$11:$G$17
Name _KyNoibo: '[3]Ky bien ban'!$C$11:$G$15
Name _KyNoibo: '[3]Ky bien ban'!$C$11:$G$15
Name _KyNoibo: '[4]Ky bien ban'!$C$11:$G$17
Name _KyNghiemthu: '[1]Ky bien ban'!$C$27:$G$31
Name _KyNghiemthu: '[1]Ky bien ban'!$C$27:$G$31
Name _KyNghiemthu: '[2]Ky bien ban'!$C$27:$G$31
Name _KyNghiemthu: '[3]Ky bien ban'!$C$25:$G$29
Name _KyNghiemthu: '[3]Ky bien ban'!$C$25:$G$29
Name _KyNghiemthu: '[4]Ky bien ban'!$C$27:$G$31
Name _KyYeucau: '[1]Ky bien ban'!$C$20:$G$24
Name _KyYeucau: '[1]Ky bien ban'!$C$20:$G$24
Name _KyYeucau: '[2]Ky bien ban'!$C$20:$G$24
Name _KyYeucau: '[3]Ky bien ban'!$C$18:$G$22
Name _KyYeucau: '[3]Ky bien ban'!$C$18:$G$22
Name _KyYeucau: '[4]Ky bien ban'!$C$20:$G$24
Name _tenchucdanh: '[1]Thong tin'!$E$10:$G$117
Name _tenchucdanh: '[1]Thong tin'!$E$10:$G$117
Name _tenchucdanh: '[2]Thong tin'!$E$10:$G$117
Name _tenchucdanh: '[3]Thong tin'!$E$10:$G$117
Name _tenchucdanh: '[3]Thong tin'!$E$10:$G$117
Name _tenchucdanh: '[4]Thong tin'!$E$10:$G$117
Name Actual: ('BÌA TỔNG-G2'!PeriodInActual*('[3]Tien do TV'!$J1>0))*'BÌA TỔNG-G2'!PeriodInPlan
Name Actual: ('Tr1-G2 '!PeriodInActual*('[3]Tien do TV'!$J1>0))*'Tr1-G2 '!PeriodInPlan
Name Actual: ([0]!PeriodInActual*('[3]Tien do TV'!$J1>0))*[0]!PeriodInPlan
Name Actual: ([0]!PeriodInActual*('[3]Tien do TV'!$J1>0))*[0]!PeriodInPlan
Name Actual: ([0]!PeriodInActual*('[3]Tien do TV'!$J1>0))*[0]!PeriodInPlan
Name Actual: (PeriodInActual*('[3]Tien do TV'!$J1>0))*PeriodInPlan
Name ActualBeyond: 'BÌA TỔNG-G2'!PeriodInActual*('[3]Tien do TV'!$J1>0)
Name ActualBeyond: 'Tr1-G2 '!PeriodInActual*('[3]Tien do TV'!$J1>0)
Name ActualBeyond: [0]!PeriodInActual*('[3]Tien do TV'!$J1>0)
Name ActualBeyond: [0]!PeriodInActual*('[3]Tien do TV'!$J1>0)
Name ActualBeyond: [0]!PeriodInActual*('[3]Tien do TV'!$J1>0)
Name ActualBeyond: PeriodInActual*('[3]Tien do TV'!$J1>0)
Name B_DMBBNTCV: '[1]Danh muc NT cong viec'!$A$7:$Z$5015
Name B_DMBBNTCV: '[1]Danh muc NT cong viec'!$A$7:$Z$5015
Name B_DMBBNTCV: '[2]Danh muc NT cong viec'!$A$7:$Z$5015
Name B_DMBBNTCV: '[3]Danh muc NT cong viec'!$A$7:$AD$5016
Name B_DMBBNTCV: '[3]Danh muc NT cong viec'!$A$7:$AD$5016
Name B_DMBBNTCV: '[4]Danh muc NT cong viec'!$A$7:$Z$5015

Sheet BÌA TỔNG-G2
A2: CỘNG HÒA XÃ HỘI CHỦ NGHĨA VIỆT NAM
A3: Độc lập - Tự do - Hạnh phúc
B6: NHẬT KÝ THI CÔNG XÂY DỰNG CÔNG TRÌNH | N6: ngày | O6: tháng | P6: năm
B7: ="THÁNG "&O7&"/"&P7&"" -> THÁNG 07/2026 | N7: 01 | O7: 07 | P7: 2026
B10: ='Biavh-Q8'!O10 -> Dự toán mua sắm: | D10: ='Biavh-Q8'!Q10 -> Cung cấp dịch vụ sự nghiệp công Công tác Quản lý, bảo trì hệ thống chiếu sáng đô thị thuộc địa bàn phường Xóm Chiếu, phường Khánh Hội, phường Vĩnh Hội, phường Bình Tây, phường Bình Tiên, phường Bình Phú, phường Phú Lâm, phường Tân Thuận, phường Phú Thuận, phường Tân Mỹ, phường Tân Hưng, phường Chánh Hưng, phường Phú Định, phường Bình Đông, xã Vĩnh Lộc, xã Tân Vĩnh Lộc, xã Bình Lợi, xã Tân Nhựt, xã Bình Chánh, xã Hưng Long, xã Bình Hưng, xã Bình Khánh, xã An Thới Đông, xã Cần Giờ, xã Nhà Bè, xã Hiệp Phước, xã Thạnh An.
B11: ='Biavh-Q8'!O11 -> Gói thầu: | D11: ='Biavh-Q8'!Q11 -> Phi tư vấn Công tác Quản lý, bảo trì hệ thống chiếu sáng đô thị thuộc địa bàn phường Xóm Chiếu, phường Khánh Hội, phường Vĩnh Hội, phường Bình Tây, phường Bình Tiên, phường Bình Phú, phường Phú Lâm, phường Tân Thuận, phường Phú Thuận, phường Tân Mỹ, phường Tân Hưng, phường Chánh Hưng, phường Phú Định, phường Bình Đông, xã Vĩnh Lộc, xã Tân Vĩnh Lộc, xã Bình Lợi, xã Tân Nhựt, xã Bình Chánh, xã Hưng Long, xã Bình Hưng, xã Bình Khánh, xã An Thới Đông, xã Cần Giờ, xã Nhà Bè, xã Hiệp Phước, xã Thạnh An.
B12: Đơn vị thi công: | D12: ='Biavh-Q8'!Q18 -> Liên danh Chiếu sáng công cộng TP.HCM - Kỹ thuật Điện Phú Thọ
B13: Đại diện liên danh: | D13: ='Biavh-Q8'!Q19 -> Công ty cổ phần Chiếu sáng công cộng TP.HCM
B14: Chủ đầu tư: | D14: ='Biavh-Q8'!Q15 -> Trung tâm Quản lý Giao thông và Hạ tầng kỹ thuật TP.HCM
H17: ="Tp. Hồ Chí Minh, ngày "&N7&" tháng "&O7&" năm "&P7&"" -> Tp. Hồ Chí Minh, ngày 01 tháng 07 năm 2026
B18: CÔNG TY CỔ PHẦN | H18: TRUNG TÂM QUẢN LÝ GIAO THÔNG VÀ
B19: CHIẾU SÁNG CÔNG CỘNG TP.HCM | H19: HẠ TẦNG KỸ THUẬT TP.HCM
B20: TỔNG GIÁM ĐỐC | H20: KT. GIÁM ĐỐC
H21: PHÓ GIÁM ĐỐC
B25: Huỳnh Trí Dũng | H25: Lê Văn Tấn

Sheet Biavh-Q8
C3: CỘNG HÒA XÃ HỘI CHỦ NGHĨA VIỆT NAM
C4: Độc lập - Tự do - Hạnh phúc
C7: NHẬT KÝ THI CÔNG
C8: XÂY DỰNG CÔNG TRÌNH
C10: Dự toán mua sắm: | E10: =Q10 -> Cung cấp dịch vụ sự nghiệp công Công tác Quản lý, bảo trì hệ thống chiếu sáng đô thị thuộc địa bàn phường Xóm Chiếu, phường Khánh Hội, phường Vĩnh Hội, phường Bình Tây, phường Bình Tiên, phường Bình Phú, phường Phú Lâm, phường Tân Thuận, phường Phú Thuận, phường Tân Mỹ, phường Tân Hưng, phường Chánh Hưng, phường Phú Định, phường Bình Đông, xã Vĩnh Lộc, xã Tân Vĩnh Lộc, xã Bình Lợi, xã Tân Nhựt, xã Bình Chánh, xã Hưng Long, xã Bình Hưng, xã Bình Khánh, xã An Thới Đông, xã Cần Giờ, xã Nhà Bè, xã Hiệp Phước, xã Thạnh An. | O10: Dự toán mua sắm: | Q10: Cung cấp dịch vụ sự nghiệp công Công tác Quản lý, bảo trì hệ thống chiếu sáng đô thị thuộc địa bàn phường Xóm Chiếu, phường Khánh Hội, phường Vĩnh Hội, phường Bình Tây, phường Bình Tiên, phường Bình Phú, phường Phú Lâm, phường Tân Thuận, phường Phú Thuận, phường Tân Mỹ, phường Tân Hưng, phường Chánh Hưng, phường Phú Định, phường Bình Đông, xã Vĩnh Lộc, xã Tân Vĩnh Lộc, xã Bình Lợi, xã Tân Nhựt, xã Bình Chánh, xã Hưng Long, xã Bình Hưng, xã Bình Khánh, xã An Thới Đông, xã Cần Giờ, xã Nhà Bè, xã Hiệp Phước, xã Thạnh An.
C11: Gói thầu: | E11: =Q11 -> Phi tư vấn Công tác Quản lý, bảo trì hệ thống chiếu sáng đô thị thuộc địa bàn phường Xóm Chiếu, phường Khánh Hội, phường Vĩnh Hội, phường Bình Tây, phường Bình Tiên, phường Bình Phú, phường Phú Lâm, phường Tân Thuận, phường Phú Thuận, phường Tân Mỹ, phường Tân Hưng, phường Chánh Hưng, phường Phú Định, phường Bình Đông, xã Vĩnh Lộc, xã Tân Vĩnh Lộc, xã Bình Lợi, xã Tân Nhựt, xã Bình Chánh, xã Hưng Long, xã Bình Hưng, xã Bình Khánh, xã An Thới Đông, xã Cần Giờ, xã Nhà Bè, xã Hiệp Phước, xã Thạnh An. | O11: Gói thầu: | Q11: Phi tư vấn Công tác Quản lý, bảo trì hệ thống chiếu sáng đô thị thuộc địa bàn phường Xóm Chiếu, phường Khánh Hội, phường Vĩnh Hội, phường Bình Tây, phường Bình Tiên, phường Bình Phú, phường Phú Lâm, phường Tân Thuận, phường Phú Thuận, phường Tân Mỹ, phường Tân Hưng, phường Chánh Hưng, phường Phú Định, phường Bình Đông, xã Vĩnh Lộc, xã Tân Vĩnh Lộc, xã Bình Lợi, xã Tân Nhựt, xã Bình Chánh, xã Hưng Long, xã Bình Hưng, xã Bình Khánh, xã An Thới Đông, xã Cần Giờ, xã Nhà Bè, xã Hiệp Phước, xã Thạnh An.
C12: Địa điểm: | E12: =Q12 -> Phường Xóm Chiếu, phường Khánh Hội, phường Vĩnh Hội, phường Bình Tây, phường Bình Tiên, phường Bình Phú, phường Phú Lâm, phường Tân Thuận, phường Phú Thuận, phường Tân Mỹ, phường Tân Hưng, phường Chánh Hưng, phường Phú Định, phường Bình Đông, xã Vĩnh Lộc, xã Tân Vĩnh Lộc, xã Bình Lợi, xã Tân Nhựt, xã Bình Chánh, xã Hưng Long, xã Bình Hưng, xã Bình Khánh, xã An Thới Đông, xã Cần Giờ, xã Nhà Bè, xã Hiệp Phước, xã Thạnh An. | O12: Địa điểm: | Q12: Phường Xóm Chiếu, phường Khánh Hội, phường Vĩnh Hội, phường Bình Tây, phường Bình Tiên, phường Bình Phú, phường Phú Lâm, phường Tân Thuận, phường Phú Thuận, phường Tân Mỹ, phường Tân Hưng, phường Chánh Hưng, phường Phú Định, phường Bình Đông, xã Vĩnh Lộc, xã Tân Vĩnh Lộc, xã Bình Lợi, xã Tân Nhựt, xã Bình Chánh, xã Hưng Long, xã Bình Hưng, xã Bình Khánh, xã An Thới Đông, xã Cần Giờ, xã Nhà Bè, xã Hiệp Phước, xã Thạnh An.
C13: Công tác: | E13: ="Quản lý, vận hành hệ thống chiếu sáng đô thị thực hiện tháng "&O13& " năm 2026." -> Quản lý, vận hành hệ thống chiếu sáng đô thị thực hiện tháng 07 năm 2026. | N13: Tháng | O13: ='BÌA TỔNG-G2'!O7 -> 07
E14: =Q14 -> Địa bàn: phường Chánh Hưng, phường Phú Định, phường Bình Đông - Thành phố Hồ Chí Minh. | Q14: Địa bàn: phường Chánh Hưng, phường Phú Định, phường Bình Đông - Thành phố Hồ Chí Minh.
C15: Bên A: | E15: =Q15 -> Trung tâm Quản lý Giao thông và Hạ tầng kỹ thuật TP.HCM | P15: Bên A | Q15: Trung tâm Quản lý Giao thông và Hạ tầng kỹ thuật TP.HCM
C16: Bên B: | E16: =Q18 -> Liên danh Chiếu sáng công cộng TP.HCM - Kỹ thuật Điện Phú Thọ | P16: Bên A | Q16: Ông Huỳnh Phước Hải
C17: Đại diện liên danh: | E17: Công ty cổ phần Chiếu sáng công cộng TP.HCM
P18: Bên B | Q18: Liên danh Chiếu sáng công cộng TP.HCM - Kỹ thuật Điện Phú Thọ
C19: * Đại diện bên A: | K19: Chữ ký | O19: Đại diện liên danh: | Q19: Công ty cổ phần Chiếu sáng công cộng TP.HCM
C20: =Q16 -> Ông Huỳnh Phước Hải | F20: Chức vụ: Chuyên viên phụ trách địa bàn | K20: ...............
C21: * Đại diện bên B: | P21: Bên B | Q21: Ông Nguyễn Thành Nam
C22: =Q21 -> Ông Nguyễn Thành Nam | F22: Chức vụ: Chỉ huy trưởng | K22: ............... | Q22: Ông Phạm Tấn Việt
C23: (Sổ này gồm.............trang, đánh số thứ tự từ 1 đến............ có đóng dấu giáp lai )
B24: Quyển số:……../tổng số…….quyển.
B27: ="THÁNG "&O13&" NĂM 2026" -> THÁNG 07 NĂM 2026

Sheet Tr1-G2 
A1: LIỆT KÊ CÁC VĂN BẢN
A2: LIÊN QUAN ĐẾN CÔNG TRÌNH
A4: TT | B4: Văn bản số ngày | C4: Cơ quan phát hành | D4: Ngày nhận | E4: Tóm tắt nội dung
A5: 1 | B5: Hợp đồng điện tử số: HD2600157625_2606301841 | C5: Trung tâm Quản lý Giao thông và Hạ tầng kỹ thuật TP. Hồ Chí Minh và Liên danh Chiếu sáng công cộng TP.HCM - Kỹ thuật Điện Phú Thọ | D5: 01/7/2026 | E5: Hợp đồng về cung cấp dịch vụ sự nghiệp công
A6: 2 | B6: Số 3881/TB-TTGTHTKT ngày 01/7/2026 | C6: Trung tâm Quản lý Giao thông và Hạ tầng kỹ thuật TP. Hồ Chí Minh | D6: 01/7/2026 | E6: Triển khai khởi công công tác Quản lý, bảo trì hệ thống chiếu sáng đô thị
A7: 3 | B7: Số 712/CTCSCC-KHVT ngày 01/7/2026 | C7: Công ty cổ phần Chiếu sáng công cộng TP.HCM | D7: 46204 | E7: Quyết định cử nhân sự chủ chốt thi công gói thầu
A8: 4 | B8: Số 4843/TTGTHTKT-CXCS1 ngày 23/7/2026 | C8: Trung tâm Quản lý Giao thông và Hạ tầng kỹ thuật TP. Hồ Chí Minh | D8: 46226 | E8: Giao khối lượng kế hoạch thực hiện Quý III năm 2026
A13: 9 | C13: ................................................ ................................................
C16: ="Từ ngày "&G17&" tháng "&H17&" năm "&I17&" đến ngày "&G19&" tháng "&H17&" năm "&I17&"" -> Từ ngày 01 tháng 07 năm 2026 đến ngày 31 tháng 07 năm 2026 | G16: ngày | H16: tháng | I16: năm
C17: ĐẠI DIỆN BÊN B LIÊN DANH CHIẾU SÁNG CÔNG CỘNG TP.HỒ CHÍ MINH - KỸ THUẬT ĐIỆN PHÚ THỌ | G17: ='BÌA TỔNG-G2'!N7 -> 01 | H17: ='BÌA TỔNG-G2'!O7 -> 07 | I17: ='BÌA TỔNG-G2'!P7 -> 2026
G19: 31
C20: Nguyễn Thành Nam

Sheet Tr2-G2
A2: 41813 | B2: DANH SÁCH CÁN BỘ KỸ THUẬT - GIÁM SÁT
B3: THAM GIA XÂY DỰNG CÔNG TRÌNH
B6: TT | C6: Họ và tên | E6: Chức danh | G6: Nhiệm vụ | I6: Chữ ký | J6: Ghi chú
B7: I | C7: Đại diện bên B:
B8: 1 | E8: Trưởng phòng KHVT | G8: Chỉ huy trưởng công trình
B9: 1 | C9: ='Biavh-Q8'!Q21 -> Ông Nguyễn Thành Nam | E9: Trưởng phòng KHVT | G9: Chỉ huy trưởng
B10: 2 | C10: ='Biavh-Q8'!Q22 -> Ông Phạm Tấn Việt | G10: Phụ trách kỹ thuật thi công
B14: II | C14: Đại diện bên A:
B15: 1 | C15: ='Biavh-Q8'!Q16 -> Ông Huỳnh Phước Hải | E15: Chuyên viên -P.QLCSCX | G15: Chuyên viên phụ trách địa bàn

Sheet vh-Q8
A1: NHẬT KÝ THI CÔNG HÀNG NGÀY
A2: ="Ngày "&N3&" tháng "&O3&" năm "&P3&"" -> Ngày 01 tháng 07 năm 2026 | N2: ngày | O2: tháng | P2: năm
A3: 1. Tình hình thời tiết | N3: 01 | O3: ='BÌA TỔNG-G2'!O7 -> 07 | P3: ='BÌA TỔNG-G2'!P7 -> 2026
D4: Buổi sáng | I4: Buổi chiều
A5: Thời tiết | D5: Bình thường | I5: Bình thường
A6: Nhiệt độ | D6: 31° - 34° | I6: =D6 -> 31° - 34°
A7: 2. Nhân lực và thiết bị thi công:
A8: 2.1. Nhân lực
C9: - Công nhân: người
C10: - Nhân lực khác:
A11: 2.2. Thiết bị thi công:
A13: 3. Tình hình diễn biến thi công, nghiệm thu công việc
A15: Stt | C15: Công tác quản lý vận hành | F15: Đơn vị tính | G15: Khối lượng thực hiện | J15: Khối lượng nghiệm thu
G16: Phường Chánh Hưng | H16: Phường Phú Định | I16: Phường Bình Đông | J16: Phường Chánh Hưng | K16: Phường Phú Định | L16: Phường Bình Đông
A17: * | C17: Tủ thường
A18: 1 | B18: . | C18: Duy trì trạm đèn < 500m | F18: trạm | G18: - | H18: - | I18: 1 | J18: - | K18: - | L18: 1
A19: 2 | B19: . | C19: Duy trì trạm đèn < 500m (trong hẻm) | F19: trạm | G19: - | H19: - | I19: - | J19: - | K19: - | L19: -
A20: 3 | B20: . | C20: Duy trì trạm đèn < 500m (khu dân cư) | F20: trạm | G20: - | H20: - | I20: - | J20: - | K20: - | L20: -
A21: 4 | B21: . | C21: Duy trì trạm đèn < 500m ngoại thành | F21: trạm | G21: - | H21: - | I21: - | J21: - | K21: - | L21: -
A22: 5 | B22: . | C22: Duy trì trạm đèn 500m - 1000m | F22: trạm | G22: - | H22: - | I22: - | J22: - | K22: - | L22: -
A23: 6 | B23: . | C23: Duy trì trạm đèn 500m - 1000m (trong hẻm) | F23: trạm | G23: - | H23: - | I23: - | J23: - | K23: - | L23: -
A24: 7 | B24: . | C24: Duy trì trạm đèn 500m - 1000m (khu dân cư) | F24: trạm | G24: - | H24: - | I24: - | J24: - | K24: - | L24: -
A25: 8 | B25: . | C25: Duy trì trạm đèn 500m - 1000m ngoại thành | F25: trạm | G25: - | H25: - | I25: - | J25: - | K25: - | L25: -
A26: 9 | B26: . | C26: Duy trì trạm đèn 1000m - 1500m | F26: trạm | G26: - | H26: - | I26: - | J26: - | K26: - | L26: -
A27: 10 | B27: . | C27: Duy trì trạm đèn 1000m - 1500m (trong hẻm) | F27: trạm | G27: - | H27: - | I27: - | J27: - | K27: - | L27: -
A28: 11 | B28: . | C28: Duy trì trạm đèn 1000m - 1500m (khu dân cư) | F28: trạm | G28: - | H28: - | I28: - | J28: - | K28: - | L28: -
A29: 12 | B29: . | C29: Duy trì trạm đèn 1000m - 1500m ngoại thành | F29: trạm | G29: - | H29: - | I29: - | J29: - | K29: - | L29: -
A30: 13 | B30: . | C30: Duy trì trạm đèn 1500m - 3000m | F30: trạm | G30: - | H30: - | I30: - | J30: - | K30: - | L30: -
... A37: 20 | B37: . | C37: Duy trì trạm đèn > 3000m ngoại thành | F37: trạm | G37: - | H37: - | I37: - | J37: - | K37: - | L37: -
A38: * | C38: Tủ kết nối
A39: 21 | B39: . | C39: Duy trì trạm đèn < 500m - kết nối về trung tâm điều khiển | F39: trạm | G39: 58 | H39: 40 | I39: 21 | J39: 58 | K39: 40 | L39: 21
A40: 22 | B40: . | C40: Duy trì trạm đèn < 500m (trong hẻm) - kết nối về trung tâm điều khiển | F40: trạm | G40: 9 | H40: 9 | I40: 7 | J40: 9 | K40: 9 | L40: 7
A41: 23 | B41: . | C41: Duy trì trạm đèn < 500m (khu dân cư) - kết nối về trung tâm điều khiển | F41: trạm | G41: 5 | H41: 1 | I41: 1 | J41: 5 | K41: 1 | L41: 1
A42: Stt | C42: Công tác quản lý vận hành | F42: Đơn vị tính | G42: Khối lượng thực hiện | J42: Khối lượng nghiệm thu
G43: Phường Chánh Hưng | H43: Phường Phú Định | I43: Phường Bình Đông | J43: Phường Chánh Hưng | K43: Phường Phú Định | L43: Phường Bình Đông
A44: 24 | B44: . | C44: Duy trì trạm đèn < 500m (ngoại thành) - kết nối về trung tâm điều khiển | F44: trạm | G44: - | H44: - | I44: - | J44: - | K44: - | L44: -
A45: 25 | B45: . | C45: Duy trì trạm đèn 500m - 1000m - kết nối về trung tâm điều khiển | F45: trạm | G45: 25 | H45: 40 | I45: 22 | J45: 25 | K45: 40 | L45: 22
A46: 26 | B46: . | C46: Duy trì trạm đèn 500m - 1000m (trong hẻm) - kết nối về trung tâm điều khiển | F46: trạm | G46: 5 | H46: - | I46: - | J46: 5 | K46: - | L46: -
A47: 27 | B47: . | C47: Duy trì trạm đèn 500m - 1000m (khu dân cư) - kết nối về trung tâm điều khiển | F47: trạm | G47: 3 | H47: 1 | I47: 8 | J47: 3 | K47: 1 | L47: 8
A48: 28 | B48: . | C48: Duy trì trạm đèn 500m - 1000m (ngoại thành) - kết nối về trung tâm điều khiển | F48: trạm | G48: - | H48: - | I48: - | J48: - | K48: - | L48: -
...

Sheet vh-G2 (Nghỉ)
A1: NHẬT KÝ THI CÔNG HÀNG NGÀY
A2: Ngày tháng năm 2026
A4: 1. Tình hình thời tiết
D5: Buổi sáng | K5: Buổi chiều
A6: Thời tiết | D6: Bình thường | K6: Bình thường
A7: Nhiệt độ
A9: 2. Nhân lực và thiết bị thi công:
A10: 2.1. Nhân lực
C11: - Công nhân: người
C12: - Nhân lực khác:
A13: 2.2. Thiết bị thi công:
A15: 3. Tình hình diễn biến thi công, nghiệm thu công việc
A85: 4. Công tác vệ sinh môi trường:
F86: Tốt | I86: Bình thường | M86: Kém
A87: 5. Công tác an toàn lao động, an toàn giao thông:
F88: Tốt | I88: Bình thường | M88: Kém
A89: 6.Nhận xét và yêu cầu của giám sát bên A:
A91: 7. Những kiến nghị đề xuất của bên B:
A95: ĐẠI DIỆN BÊN A | K95: ĐẠI DIỆN BÊN B
B97: ='Biavh-Q8'!Q16&" …............." -> Ông Huỳnh Phước Hải …............. | E97: Ông Nguyễn Ngọc Huấn ………….. | K97: ='Biavh-Q8'!Q22&" ….................." -> Ông Phạm Tấn Việt …..................

Sheet Biadtu-Q8
C3: CỘNG HÒA XÃ HỘI CHỦ NGHĨA VIỆT NAM
C4: Độc lập - Tự do - Hạnh phúc
C7: NHẬT KÝ THI CÔNG
C8: XÂY DỰNG CÔNG TRÌNH
C10: Dự toán mua sắm: | E10: ='Biavh-Q8'!Q10 -> Cung cấp dịch vụ sự nghiệp công Công tác Quản lý, bảo trì hệ thống chiếu sáng đô thị thuộc địa bàn phường Xóm Chiếu, phường Khánh Hội, phường Vĩnh Hội, phường Bình Tây, phường Bình Tiên, phường Bình Phú, phường Phú Lâm, phường Tân Thuận, phường Phú Thuận, phường Tân Mỹ, phường Tân Hưng, phường Chánh Hưng, phường Phú Định, phường Bình Đông, xã Vĩnh Lộc, xã Tân Vĩnh Lộc, xã Bình Lợi, xã Tân Nhựt, xã Bình Chánh, xã Hưng Long, xã Bình Hưng, xã Bình Khánh, xã An Thới Đông, xã Cần Giờ, xã Nhà Bè, xã Hiệp Phước, xã Thạnh An.
C11: Gói thầu: | E11: ='Biavh-Q8'!Q11 -> Phi tư vấn Công tác Quản lý, bảo trì hệ thống chiếu sáng đô thị thuộc địa bàn phường Xóm Chiếu, phường Khánh Hội, phường Vĩnh Hội, phường Bình Tây, phường Bình Tiên, phường Bình Phú, phường Phú Lâm, phường Tân Thuận, phường Phú Thuận, phường Tân Mỹ, phường Tân Hưng, phường Chánh Hưng, phường Phú Định, phường Bình Đông, xã Vĩnh Lộc, xã Tân Vĩnh Lộc, xã Bình Lợi, xã Tân Nhựt, xã Bình Chánh, xã Hưng Long, xã Bình Hưng, xã Bình Khánh, xã An Thới Đông, xã Cần Giờ, xã Nhà Bè, xã Hiệp Phước, xã Thạnh An.
C12: Địa điểm: | E12: ='Biavh-Q8'!Q12 -> Phường Xóm Chiếu, phường Khánh Hội, phường Vĩnh Hội, phường Bình Tây, phường Bình Tiên, phường Bình Phú, phường Phú Lâm, phường Tân Thuận, phường Phú Thuận, phường Tân Mỹ, phường Tân Hưng, phường Chánh Hưng, phường Phú Định, phường Bình Đông, xã Vĩnh Lộc, xã Tân Vĩnh Lộc, xã Bình Lợi, xã Tân Nhựt, xã Bình Chánh, xã Hưng Long, xã Bình Hưng, xã Bình Khánh, xã An Thới Đông, xã Cần Giờ, xã Nhà Bè, xã Hiệp Phước, xã Thạnh An.
C13: Công tác: | E13: ="Bảo dưỡng hệ thống chiếu sáng đô thị thực hiện tháng "&'Biavh-Q8'!O13& " năm 2026." -> Bảo dưỡng hệ thống chiếu sáng đô thị thực hiện tháng 07 năm 2026.
E14: ='Biavh-Q8'!Q14 -> Địa bàn: phường Chánh Hưng, phường Phú Định, phường Bình Đông - Thành phố Hồ Chí Minh.
C15: Bên A: | E15: ='Biavh-Q8'!Q15 -> Trung tâm Quản lý Giao thông và Hạ tầng kỹ thuật TP.HCM
C16: Bên B: | E16: ='Biavh-Q8'!Q18 -> Liên danh Chiếu sáng công cộng TP.HCM - Kỹ thuật Điện Phú Thọ
C17: Đại diện liên danh: | E17: Công ty cổ phần Chiếu sáng công cộng TP.HCM
C19: * Đại diện bên A: | K19: Chữ ký
C20: ='Biavh-Q8'!Q16 -> Ông Huỳnh Phước Hải | F20: Chức vụ: Chuyên viên phụ trách địa bàn | K20: ...............
C21: * Đại diện bên B:
C22: ='Biavh-Q8'!Q21 -> Ông Nguyễn Thành Nam | F22: Chức vụ: Chỉ huy trưởng | K22: ...............
C23: (Sổ này gồm.............trang, đánh số thứ tự từ 1 đến............ có đóng dấu giáp lai )
B24: Quyển số:……../tổng số…….quyển.
B27: ="THÁNG "&'Biavh-Q8'!O13&" NĂM 2026" -> THÁNG 07 NĂM 2026
